<mujoco model="panda">
  <compiler angle="radian" meshdir="assets" autolimits="true"/>

  <option integrator="implicitfast"/>

  <default>
    <default class="panda_2nd">
      <material specular="0.5" shininess="0.25"/>
      <joint armature="0.1" damping="1" axis="0 0 1" range="-2.8973 2.8973"/>
      <general dyntype="none" biastype="affine" ctrlrange="-2.8973 2.8973" forcerange="-87 87"/>
      <default class="finger_2nd">
        <joint axis="0 1 0" type="slide" range="0 0.04"/>
      </default>

      <default class="visual_2nd">
        <geom type="mesh" contype="0" conaffinity="0" group="2"/>
      </default>
      <default class="collision_2nd">
        <geom type="mesh" group="3"/>
        <default class="fingertip_pad_collision_1_2nd">
          <geom type="box" size="0.0085 0.004 0.0085" pos="0 0.0055 0.0445"/>
        </default>
        <default class="fingertip_pad_collision_2_2nd">
          <geom type="box" size="0.003 0.002 0.003" pos="0.0055 0.002 0.05"/>
        </default>
        <default class="fingertip_pad_collision_3_2nd">
          <geom type="box" size="0.003 0.002 0.003" pos="-0.0055 0.002 0.05"/>
        </default>
        <default class="fingertip_pad_collision_4_2nd">
          <geom type="box" size="0.003 0.002 0.0035" pos="0.0055 0.002 0.0395"/>
        </default>
        <default class="fingertip_pad_collision_5_2nd">
          <geom type="box" size="0.003 0.002 0.0035" pos="-0.0055 0.002 0.0395"/>
        </default>
      </default>
    </default>
  </default>

  

  <worldbody>
    <light name="top_2nd" pos="0 0 2" mode="trackcom"/>
    <body name="link0_2nd" childclass="panda_2nd" pos="2. 0 0" quat="0 0 0 1">
      <inertial mass="0.629769" pos="-0.041018 -0.00014 0.049974"
        fullinertia="0.00315 0.00388 0.004285 8.2904e-7 0.00015 8.2299e-6"/>
      <geom mesh="link0_0" material="off_white" class="visual_2nd"/>
      <geom mesh="link0_1" material="black" class="visual_2nd"/>
      <geom mesh="link0_2" material="off_white" class="visual_2nd"/>
      <geom mesh="link0_3" material="black" class="visual_2nd"/>
      <geom mesh="link0_4" material="off_white" class="visual_2nd"/>
      <geom mesh="link0_5" material="black" class="visual_2nd"/>
      <geom mesh="link0_7" material="white" class="visual_2nd"/>
      <geom mesh="link0_8" material="white" class="visual_2nd"/>
      <geom mesh="link0_9" material="black" class="visual_2nd"/>
      <geom mesh="link0_10" material="off_white" class="visual_2nd"/>
      <geom mesh="link0_11" material="white" class="visual_2nd"/>
      <geom mesh="link0_c" class="collision_2nd"/>
      <body name="link1_2nd" pos="0 0 0.333">
        <inertial mass="4.970684" pos="0.003875 0.002081 -0.04762"
          fullinertia="0.70337 0.70661 0.0091170 -0.00013900 0.0067720 0.019169"/>
        <joint name="joint1_2nd"/>
        <geom material="white" mesh="link1" class="visual_2nd"/>
        <geom mesh="link1_c" class="collision_2nd"/>
        <body name="link2_2nd" quat="1 -1 0 0">
          <inertial mass="0.646926" pos="-0.003141 -0.02872 0.003495"
            fullinertia="0.0079620 2.8110e-2 2.5995e-2 -3.925e-3 1.0254e-2 7.04e-4"/>
          <joint name="joint2_2nd" range="-1.7628 1.7628"/>
          <geom material="white" mesh="link2" class="visual_2nd"/>
          <geom mesh="link2_c" class="collision_2nd"/>
          <body name="link3_2nd" pos="0 -0.316 0" quat="1 1 0 0">
            <joint name="joint3_2nd"/>
            <inertial mass="3.228604" pos="2.7518e-2 3.9252e-2 -6.6502e-2"
              fullinertia="3.7242e-2 3.6155e-2 1.083e-2 -4.761e-3 -1.1396e-2 -1.2805e-2"/>
            <geom mesh="link3_0" material="white" class="visual_2nd"/>
            <geom mesh="link3_1" material="white" class="visual_2nd"/>
            <geom mesh="link3_2" material="white" class="visual_2nd"/>
            <geom mesh="link3_3" material="black" class="visual_2nd"/>
            <geom mesh="link3_c" class="collision_2nd"/>
            <body name="link4_2nd" pos="0.0825 0 0" quat="1 1 0 0">
              <inertial mass="3.587895" pos="-5.317e-2 1.04419e-1 2.7454e-2"
                fullinertia="2.5853e-2 1.9552e-2 2.8323e-2 7.796e-3 -1.332e-3 8.641e-3"/>
              <joint name="joint4_2nd" range="-3.0718 -0.0698"/>
              <geom mesh="link4_0" material="white" class="visual_2nd"/>
              <geom mesh="link4_1" material="white" class="visual_2nd"/>
              <geom mesh="link4_2" material="black" class="visual_2nd"/>
              <geom mesh="link4_3" material="white" class="visual_2nd"/>
              <geom mesh="link4_c" class="collision_2nd"/>
              <body name="link5_2nd" pos="-0.0825 0.384 0" quat="1 -1 0 0">
                <inertial mass="1.225946" pos="-1.1953e-2 4.1065e-2 -3.8437e-2"
                  fullinertia="3.5549e-2 2.9474e-2 8.627e-3 -2.117e-3 -4.037e-3 2.29e-4"/>
                <joint name="joint5_2nd"/>
                <geom mesh="link5_0" material="black" class="visual_2nd"/>
                <geom mesh="link5_1" material="white" class="visual_2nd"/>
                <geom mesh="link5_2" material="white" class="visual_2nd"/>
                <geom mesh="link5_c0" class="collision_2nd"/>
                <geom mesh="link5_c1" class="collision_2nd"/>
                <geom mesh="link5_c2" class="collision_2nd"/>
                <body name="link6_2nd" quat="1 1 0 0">
                  <inertial mass="1.666555" pos="6.0149e-2 -1.4117e-2 -1.0517e-2"
                    fullinertia="1.964e-3 4.354e-3 5.433e-3 1.09e-4 -1.158e-3 3.41e-4"/>
                  <joint name="joint6_2nd" range="-0.0175 3.7525"/>
                  <geom mesh="link6_0" material="off_white" class="visual_2nd"/>
                  <geom mesh="link6_1" material="white" class="visual_2nd"/>
                  <geom mesh="link6_2" material="black" class="visual_2nd"/>
                  <geom mesh="link6_3" material="white" class="visual_2nd"/>
                  <geom mesh="link6_4" material="white" class="visual_2nd"/>
                  <geom mesh="link6_5" material="white" class="visual_2nd"/>
                  <geom mesh="link6_6" material="white" class="visual_2nd"/>
                  <geom mesh="link6_7" material="light_blue" class="visual_2nd"/>
                  <geom mesh="link6_8" material="light_blue" class="visual_2nd"/>
                  <geom mesh="link6_9" material="black" class="visual_2nd"/>
                  <geom mesh="link6_10" material="black" class="visual_2nd"/>
                  <geom mesh="link6_11" material="white" class="visual_2nd"/>
                  <geom mesh="link6_12" material="green" class="visual_2nd"/>
                  <geom mesh="link6_13" material="white" class="visual_2nd"/>
                  <geom mesh="link6_14" material="black" class="visual_2nd"/>
                  <geom mesh="link6_15" material="black" class="visual_2nd"/>
                  <geom mesh="link6_16" material="white" class="visual_2nd"/>
                  <geom mesh="link6_c" class="collision_2nd"/>
                  <body name="link7_2nd" pos="0.088 0 0" quat="1 1 0 0">
                    <inertial mass="7.35522e-01" pos="1.0517e-2 -4.252e-3 6.1597e-2"
                      fullinertia="1.2516e-2 1.0027e-2 4.815e-3 -4.28e-4 -1.196e-3 -7.41e-4"/>
                    <joint name="joint7_2nd"/>
                    <geom mesh="link7_0" material="white" class="visual_2nd"/>
                    <geom mesh="link7_1" material="black" class="visual_2nd"/>
                    <geom mesh="link7_2" material="black" class="visual_2nd"/>
                    <geom mesh="link7_3" material="black" class="visual_2nd"/>
                    <geom mesh="link7_4" material="black" class="visual_2nd"/>
                    <geom mesh="link7_5" material="black" class="visual_2nd"/>
                    <geom mesh="link7_6" material="black" class="visual_2nd"/>
                    <geom mesh="link7_7" material="white" class="visual_2nd"/>
                    <geom mesh="link7_c" class="collision_2nd"/>
                    <body name="hand_2nd" pos="0 0 0.107" quat="0.9238795 0 0 -0.3826834">
                      <inertial mass="0.73" pos="-0.01 0 0.03" diaginertia="0.001 0.0025 0.0017"/>
                      <geom mesh="hand_0" material="off_white" class="visual_2nd"/>
                      <geom mesh="hand_1" material="black" class="visual_2nd"/>
                      <geom mesh="hand_2" material="black" class="visual_2nd"/>
                      <geom mesh="hand_3" material="white" class="visual_2nd"/>
                      <geom mesh="hand_4" material="off_white" class="visual_2nd"/>
                      <geom mesh="hand_c" class="collision_2nd"/>
                      <body name="left_finger_2nd" pos="0 0 0.0584">
                        <inertial mass="0.015" pos="0 0 0" diaginertia="2.375e-6 2.375e-6 7.5e-7"/>
                        <joint name="finger_joint1_2nd" class="finger_2nd"/>
                        <geom mesh="finger_0" material="off_white" class="visual_2nd"/>
                        <geom mesh="finger_1" material="black" class="visual_2nd"/>
                        <geom mesh="finger_0" class="collision_2nd"/>
                        <geom class="fingertip_pad_collision_1_2nd"/>
                        <geom class="fingertip_pad_collision_2_2nd"/>
                        <geom class="fingertip_pad_collision_3_2nd"/>
                        <geom class="fingertip_pad_collision_4_2nd"/>
                        <geom class="fingertip_pad_collision_5_2nd"/>
                      </body>
                      <body name="right_finger_2nd" pos="0 0 0.0584" quat="0 0 0 1">
                        <inertial mass="0.015" pos="0 0 0" diaginertia="2.375e-6 2.375e-6 7.5e-7"/>
                        <joint name="finger_joint2_2nd" class="finger_2nd"/>
                        <geom mesh="finger_0" material="off_white" class="visual_2nd"/>
                        <geom mesh="finger_1" material="black" class="visual_2nd"/>
                        <geom mesh="finger_0" class="collision_2nd"/>
                        <geom class="fingertip_pad_collision_1_2nd"/>
                        <geom class="fingertip_pad_collision_2_2nd"/>
                        <geom class="fingertip_pad_collision_3_2nd"/>
                        <geom class="fingertip_pad_collision_4_2nd"/>
                        <geom class="fingertip_pad_collision_5_2nd"/>
                      </body>
                    </body>
                  </body>
                </body>
              </body>
            </body>
          </body>
        </body>
      </body>
    </body>
  </worldbody>

  <tendon>
    <fixed name="split_2nd">
      <joint joint="finger_joint1_2nd" coef="0.5"/>
      <joint joint="finger_joint2_2nd" coef="0.5"/>
    </fixed>
  </tendon>

  <equality>
    <joint joint1="finger_joint1_2nd" joint2="finger_joint2_2nd" solimp="0.95 0.99 0.001" solref="0.005 1"/>
  </equality>

  <actuator>
    <general class="panda_2nd" name="actuator1_2nd" joint="joint1_2nd" gainprm="4500" biasprm="0 -4500 -450"/>
    <general class="panda_2nd" name="actuator2_2nd" joint="joint2_2nd" gainprm="4500" biasprm="0 -4500 -450"
      ctrlrange="-1.7628 1.7628"/>
    <general class="panda_2nd" name="actuator3_2nd" joint="joint3_2nd" gainprm="3500" biasprm="0 -3500 -350"/>
    <general class="panda_2nd" name="actuator4_2nd" joint="joint4_2nd" gainprm="3500" biasprm="0 -3500 -350"
      ctrlrange="-3.0718 -0.0698"/>
    <general class="panda_2nd" name="actuator5_2nd" joint="joint5_2nd" gainprm="2000" biasprm="0 -2000 -200" forcerange="-12 12"/>
    <general class="panda_2nd" name="actuator6_2nd" joint="joint6_2nd" gainprm="2000" biasprm="0 -2000 -200" forcerange="-12 12"
      ctrlrange="-0.0175 3.7525"/>
    <general class="panda_2nd" name="actuator7_2nd" joint="joint7_2nd" gainprm="2000" biasprm="0 -2000 -200" forcerange="-12 12"/>
    <!-- Remap original ctrlrange (0, 0.04) to (0, 255): 0.04 * 100 / 255 = 0.01568627451 -->
    <general class="panda_2nd" name="actuator8_2nd" tendon="split_2nd" forcerange="-100 100" ctrlrange="0 255"
      gainprm="0.01568627451 0 0" biasprm="0 -100 -10"/>
  </actuator>

  <keyframe>
    <key name="home_2nd" qpos="0 0 0 -1.57079 0 1.57079 -0.7853 0.04 0.04" ctrl="0 0 0 -1.57079 0 1.57079 -0.7853 255"/>
  </keyframe>

  <contact>
    <exclude body1="link0_2nd" body2="link1_2nd"/>
  </contact>
</mujoco>
